<?xml version="1.0" ?>
<!-- =================================================================================== -->
<!-- |    This document was autogenerated by xacro from ./SNTRobot.urdf.xacro          | -->
<!-- |    EDITING THIS FILE BY HAND IS NOT RECOMMENDED                                 | -->
<!-- =================================================================================== -->
<robot name="SNTRobot">
  <!-- ====== 몸통의 형태 정의 ====== -->
  <!-- 링크 길이들 -->
  <!-- ====== 재질(색) 정의 ====== -->
  <material name="mat_black">
    <color rgba="0.05 0.05 0.05 1.0"/>
  </material>
  <material name="mat_orange">
    robot
    
    <color rgba="1.0 0.45 0.0 1.0"/>
  </material>
  <!-- ====== 박스 링크 생성
       링크 프레임 원점은 joint 위치(링크 시작점)에 둠
       박스는 +Z로 뻗도록 z=length/2로 올림
  ====== -->
  <!-- ====== 조인트 매크로(핵심: rpy를 인자로 받는다) ====== -->
  <!-- ====== base ====== -->
  <link name="base_link">
    <visual>
      <origin rpy="0 0 0" xyz="0 0 0.05"/>
      <geometry>
        <box size="0.20 0.20 0.10"/>
      </geometry>
      <material name="mat_black"/>
    </visual>
    <collision>
      <origin rpy="0 0 0" xyz="0 0 0.05"/>
      <geometry>
        <box size="0.20 0.20 0.10"/>
      </geometry>
    </collision>
  </link>
  <!-- ====== links (검/주 반복) ====== -->
  <link name="link1">
    <inertial>
      <origin rpy="0 0 0" xyz="0 0 0"/>
      <mass value="1.0"/>
      <inertia ixx="0.01" ixy="0" ixz="0" iyy="0.01" iyz="0" izz="0.01"/>
    </inertial>
    <visual>
      <origin rpy="0 0 0" xyz="0 0 0.125"/>
      <geometry>
        <box size="0.06 0.06 0.25"/>
      </geometry>
      <material name="mat_black"/>
    </visual>
    <collision>
      <origin rpy="0 0 0" xyz="0 0 0.125"/>
      <geometry>
        <box size="0.06 0.06 0.25"/>
      </geometry>
    </collision>
  </link>
  <link name="link2">
    <inertial>
      <origin rpy="0 0 0" xyz="0 0 0"/>
      <mass value="1.0"/>
      <inertia ixx="0.01" ixy="0" ixz="0" iyy="0.01" iyz="0" izz="0.01"/>
    </inertial>
    <visual>
      <origin rpy="0 0 0" xyz="0 0 0.05"/>
      <geometry>
        <box size="0.06 0.06 0.1"/>
      </geometry>
      <material name="mat_orange"/>
    </visual>
    <collision>
      <origin rpy="0 0 0" xyz="0 0 0.05"/>
      <geometry>
        <box size="0.06 0.06 0.1"/>
      </geometry>
    </collision>
  </link>
  <link name="link3">
    <inertial>
      <origin rpy="0 0 0" xyz="0 0 0"/>
      <mass value="1.0"/>
      <inertia ixx="0.01" ixy="0" ixz="0" iyy="0.01" iyz="0" izz="0.01"/>
    </inertial>
    <visual>
      <origin rpy="0 0 0" xyz="0 0 0.125"/>
      <geometry>
        <box size="0.06 0.06 0.25"/>
      </geometry>
      <material name="mat_black"/>
    </visual>
    <collision>
      <origin rpy="0 0 0" xyz="0 0 0.125"/>
      <geometry>
        <box size="0.06 0.06 0.25"/>
      </geometry>
    </collision>
  </link>
  <link name="link4">
    <inertial>
      <origin rpy="0 0 0" xyz="0 0 0"/>
      <mass value="1.0"/>
      <inertia ixx="0.01" ixy="0" ixz="0" iyy="0.01" iyz="0" izz="0.01"/>
    </inertial>
    <visual>
      <origin rpy="0 0 0" xyz="0 0 0.05"/>
      <geometry>
        <box size="0.06 0.06 0.1"/>
      </geometry>
      <material name="mat_orange"/>
    </visual>
    <collision>
      <origin rpy="0 0 0" xyz="0 0 0.05"/>
      <geometry>
        <box size="0.06 0.06 0.1"/>
      </geometry>
    </collision>
  </link>
  <link name="link5">
    <inertial>
      <origin rpy="0 0 0" xyz="0 0 0"/>
      <mass value="1.0"/>
      <inertia ixx="0.01" ixy="0" ixz="0" iyy="0.01" iyz="0" izz="0.01"/>
    </inertial>
    <visual>
      <origin rpy="0 0 0" xyz="0 0 0.125"/>
      <geometry>
        <box size="0.06 0.06 0.25"/>
      </geometry>
      <material name="mat_black"/>
    </visual>
    <collision>
      <origin rpy="0 0 0" xyz="0 0 0.125"/>
      <geometry>
        <box size="0.06 0.06 0.25"/>
      </geometry>
    </collision>
  </link>
  <link name="link6">
    <inertial>
      <origin rpy="0 0 0" xyz="0 0 0"/>
      <mass value="1.0"/>
      <inertia ixx="0.01" ixy="0" ixz="0" iyy="0.01" iyz="0" izz="0.01"/>
    </inertial>
    <visual>
      <origin rpy="0 0 0" xyz="0 0 0.05"/>
      <geometry>
        <box size="0.06 0.06 0.1"/>
      </geometry>
      <material name="mat_orange"/>
    </visual>
    <collision>
      <origin rpy="0 0 0" xyz="0 0 0.05"/>
      <geometry>
        <box size="0.06 0.06 0.1"/>
      </geometry>
    </collision>
  </link>
  <link name="link7">
    <inertial>
      <origin rpy="0 0 0" xyz="0 0 0"/>
      <mass value="1.0"/>
      <inertia ixx="0.01" ixy="0" ixz="0" iyy="0.01" iyz="0" izz="0.01"/>
    </inertial>
    <visual>
      <origin rpy="0 0 0" xyz="0 0 0.05"/>
      <geometry>
        <box size="0.06 0.06 0.1"/>
      </geometry>
      <material name="mat_black"/>
    </visual>
    <collision>
      <origin rpy="0 0 0" xyz="0 0 0.05"/>
      <geometry>
        <box size="0.06 0.06 0.1"/>
      </geometry>
    </collision>
  </link>
  <joint name="joint1" type="revolute">
    <parent link="base_link"/>
    <child link="link1"/>
    <origin rpy="0 0 0" xyz="0 0 0.10"/>
    <axis xyz="0 0 1"/>
    <limit effort="50" lower="-3.1416" upper="3.1416" velocity="2.0"/>
    <dynamics damping="0.1" friction="0.0"/>
  </joint>
  <joint name="joint2" type="revolute">
    <parent link="link1"/>
    <child link="link2"/>
    <origin rpy="1.5708 0 0" xyz="0 0 0.25"/>
    <axis xyz="0 0 -1"/>
    <limit effort="50" lower="-3.1416" upper="3.1416" velocity="2.0"/>
    <dynamics damping="0.1" friction="0.0"/>
  </joint>
  <joint name="fix_joint" type="fixed">
    <parent link="link2"/>
    <child link="link3"/>
    <origin rpy="-1.5708 0 0" xyz="0 0 0.1"/>
  </joint>
  <joint name="joint3" type="revolute">
    <parent link="link3"/>
    <child link="link4"/>
    <origin rpy="-1.5708 0 0" xyz="0 0 0.25"/>
    <axis xyz="0 0 1"/>
    <limit effort="50" lower="-3.1416" upper="3.1416" velocity="2.0"/>
    <dynamics damping="0.1" friction="0.0"/>
  </joint>
  <joint name="joint4" type="revolute">
    <parent link="link4"/>
    <child link="link5"/>
    <origin rpy="1.5708 0 0" xyz="0 0 0.1"/>
    <axis xyz="0 0 1"/>
    <limit effort="50" lower="-3.1416" upper="3.1416" velocity="2.0"/>
    <dynamics damping="0.1" friction="0.0"/>
  </joint>
  <joint name="joint5" type="revolute">
    <parent link="link5"/>
    <child link="link6"/>
    <origin rpy="1.5708 0 0" xyz="0 0 0.25"/>
    <axis xyz="0 0 -1"/>
    <limit effort="50" lower="-3.1416" upper="3.1416" velocity="2.0"/>
    <dynamics damping="0.1" friction="0.0"/>
  </joint>
  <joint name="joint6" type="revolute">
    <parent link="link6"/>
    <child link="link7"/>
    <origin rpy="-1.5708 0 0" xyz="0 0 0.1"/>
    <axis xyz="0 0 1"/>
    <limit effort="50" lower="-3.1416" upper="3.1416" velocity="2.0"/>
    <dynamics damping="0.1" friction="0.0"/>
  </joint>
</robot>
